<?xml version="1.0" ?>
<robot name="turtlebot3_waffle" xmlns:xacro="http://ros.org/wiki/xacro">
  <!-- <xacro:include filename="$(find turtlebot3_description)/urdf/common_properties.urdf"/>

  <xacro:property name="r200_cam_rgb_px" value="0.005"/>
  <xacro:property name="r200_cam_rgb_py" value="0.018"/>
  <xacro:property name="r200_cam_rgb_pz" value="0.013"/>
  <xacro:property name="r200_cam_depth_offset" value="0.01"/> -->
  <xacro:arg name="namespace" default=""/>
  <xacro:property name="namespace" value="$(arg namespace)"/>
  <!-- Init colour -->
  <material name="black">
      <color rgba="0.0 0.0 0.0 1.0"/>
  </material>

  <material name="dark">
    <color rgba="0.3 0.3 0.3 1.0"/>
  </material>

  <material name="light_black">
    <color rgba="0.4 0.4 0.4 1.0"/>
  </material>

  <material name="blue">
    <color rgba="0.0 0.0 0.8 1.0"/>
  </material>

  <material name="green">
    <color rgba="0.0 0.8 0.0 1.0"/>
  </material>

  <material name="grey">
    <color rgba="0.5 0.5 0.5 1.0"/>
  </material>

  <material name="orange">
    <color rgba="1.0 0.4235 0.0392 1.0"/>
  </material>

  <material name="brown">
    <color rgba="0.8706 0.8118 0.7647 1.0"/>
  </material>

  <material name="red">
    <color rgba="0.8 0.0 0.0 1.0"/>
  </material>

  <material name="white">
    <color rgba="1.0 1.0 1.0 1.0"/>
  </material>

  <link name="${namespace}base_footprint"/>

  <joint name="${namespace}base_joint" type="fixed">
    <parent link="${namespace}base_footprint"/>
    <child link="${namespace}base_link" />
    <origin xyz="0 0 0.010" rpy="0 0 0"/>
  </joint>

  <link name="${namespace}base_link">
    <visual>
      <origin xyz="-0.064 0 0.0" rpy="0 0 0"/>
      <geometry>
        <mesh filename="package://turtlebot3_description/meshes/bases/waffle_base.stl" scale="0.001 0.001 0.001"/>
      </geometry>
      <material name="light_black"/>
    </visual>

    <collision>
      <origin xyz="-0.064 0 0.047" rpy="0 0 0"/>
      <geometry>
        <box size="0.266 0.266 0.094"/>
      </geometry>
    </collision>

    <inertial>
      <origin xyz="0 0 0" rpy="0 0 0"/>
      <mass value="1.3729096e+00"/>
      <inertia ixx="8.7002718e-03" ixy="-4.7576583e-05" ixz="1.1160499e-04"
               iyy="8.6195418e-03" iyz="-3.5422299e-06"
               izz="1.4612727e-02" />
    </inertial>
  </link>

  <joint name="${namespace}wheel_left_joint" type="continuous">
    <parent link="${namespace}base_link"/>
    <child link="${namespace}wheel_left_link"/>
    <origin xyz="0.0 0.144 0.023" rpy="-1.57 0 0"/>
    <axis xyz="0 0 1"/>
  </joint>

  <link name="${namespace}wheel_left_link">
    <visual>
      <origin xyz="0 0 0" rpy="1.57 0 0"/>
      <geometry>
        <mesh filename="package://turtlebot3_description/meshes/wheels/left_tire.stl" scale="0.001 0.001 0.001"/>
      </geometry>
      <material name="dark"/>
    </visual>

    <collision>
      <origin xyz="0 0 0" rpy="0 0 0"/>
      <geometry>
        <cylinder length="0.018" radius="0.033"/>
      </geometry>
    </collision>

    <inertial>
      <origin xyz="0 0 0" />
      <mass value="2.8498940e-02" />
      <inertia ixx="1.1175580e-05" ixy="-4.2369783e-11" ixz="-5.9381719e-09"
               iyy="1.1192413e-05" iyz="-1.4400107e-11"
               izz="2.0712558e-05" />
      </inertial>
  </link>

  <joint name="${namespace}wheel_right_joint" type="continuous">
    <parent link="${namespace}base_link"/>
    <child link="${namespace}wheel_right_link"/>
    <origin xyz="0.0 -0.144 0.023" rpy="-1.57 0 0"/>
    <axis xyz="0 0 1"/>
  </joint>

  <link name="${namespace}wheel_right_link">
    <visual>
      <origin xyz="0 0 0" rpy="1.57 0 0"/>
      <geometry>
        <mesh filename="package://turtlebot3_description/meshes/wheels/right_tire.stl" scale="0.001 0.001 0.001"/>
      </geometry>
      <material name="dark"/>
    </visual>

    <collision>
      <origin xyz="0 0 0" rpy="0 0 0"/>
      <geometry>
        <cylinder length="0.018" radius="0.033"/>
      </geometry>
    </collision>

    <inertial>
      <origin xyz="0 0 0" />
      <mass value="2.8498940e-02" />
      <inertia ixx="1.1175580e-05" ixy="-4.2369783e-11" ixz="-5.9381719e-09"
               iyy="1.1192413e-05" iyz="-1.4400107e-11"
               izz="2.0712558e-05" />
      </inertial>
  </link>

  <joint name="${namespace}caster_back_right_joint" type="fixed">
    <parent link="${namespace}base_link"/>
    <child link="${namespace}caster_back_right_link"/>
    <origin xyz="-0.177 -0.064 -0.004" rpy="-1.57 0 0"/>
  </joint>

  <link name="${namespace}caster_back_right_link">
    <collision>
      <origin xyz="0 0.001 0" rpy="0 0 0"/>
      <geometry>
        <box size="0.030 0.009 0.020"/>
      </geometry>
    </collision>

    <inertial>
      <origin xyz="0 0 0" />
      <mass value="0.005" />
      <inertia ixx="0.001" ixy="0.0" ixz="0.0"
               iyy="0.001" iyz="0.0"
               izz="0.001" />
    </inertial>
  </link>

  <joint name="${namespace}caster_back_left_joint" type="fixed">
    <parent link="${namespace}base_link"/>
    <child link="${namespace}caster_back_left_link"/>
    <origin xyz="-0.177 0.064 -0.004" rpy="-1.57 0 0"/>
  </joint>

  <link name="${namespace}caster_back_left_link">
    <collision>
      <origin xyz="0 0.001 0" rpy="0 0 0"/>
      <geometry>
        <box size="0.030 0.009 0.020"/>
      </geometry>
    </collision>

    <inertial>
      <origin xyz="0 0 0" />
      <mass value="0.005" />
      <inertia ixx="0.001" ixy="0.0" ixz="0.0"
               iyy="0.001" iyz="0.0"
               izz="0.001" />
    </inertial>
  </link>

  <joint name="${namespace}imu_joint" type="fixed">
    <parent link="${namespace}base_link"/>
    <child link="${namespace}imu_link"/>
    <origin xyz="0.0 0 0.068" rpy="0 0 0"/>
  </joint>

  <link name="${namespace}imu_link"/>

  <joint name="${namespace}scan_joint" type="fixed">
    <parent link="${namespace}base_link"/>
    <child link="${namespace}base_scan"/>
    <origin xyz="-0.064 0 0.122" rpy="0 0 0"/>
  </joint>

  <link name="${namespace}base_scan">
    <visual>
      <origin xyz="0 0 0" rpy="0 0 0"/>
      <geometry>
        <mesh filename="package://turtlebot3_description/meshes/sensors/lds.stl" scale="0.001 0.001 0.001"/>
      </geometry>
      <material name="dark"/>
    </visual>

    <collision>
      <origin xyz="0.015 0 -0.0065" rpy="0 0 0"/>
      <geometry>
        <cylinder length="0.0315" radius="0.055"/>
      </geometry>
    </collision>

    <inertial>
      <mass value="0.114" />
      <origin xyz="0 0 0" />
      <inertia ixx="0.001" ixy="0.0" ixz="0.0"
               iyy="0.001" iyz="0.0"
               izz="0.001" />
    </inertial>
  </link>

  <joint name="oakd_joint" type="fixed">
    <parent link="base_link"/>
    <child link="oakd_link"/>
    <origin xyz="0.064 0 0.094" rpy="0 0.26 0"/>
  </joint>

  <link name="oakd_link">
    <visual>
      <origin xyz="0 0 0" rpy="1.5708 0 1.5708"/> 
      <geometry>
        <mesh filename="package://tb3_autonomy/meshes/OAK-D-PRO.stl"/>
      </geometry>
      <material name="dark"/>
    </visual>
    <collision>
      <origin xyz="0 0 0" rpy="1.57 0 1.57"/>
      <geometry>
        <box size="0.03 0.11 0.03"/>
      </geometry>
    </collision>
    <inertial>
      <mass value="0.1"/>
      <inertia ixx="0.001" ixy="0" ixz="0" iyy="0.001" iyz="0" izz="0.001" />
    </inertial>
  </link>

  <joint name="oakd_imu_joint" type="fixed">
    <parent link="oakd_link"/>
    <child link="oakd_imu_frame"/>
    <origin xyz="-0.008 -0.037945 -0.00079" rpy="3.14159 1.5708 0"/>
  </joint>
  <link name="oakd_imu_frame"/>

  <joint name="oakd_rgb_joint" type="fixed">
    <parent link="oakd_link"/>
    <child link="oakd_rgb_frame"/>
    <origin xyz="0 0 0" rpy="0 0 0"/>
  </joint>
  <link name="oakd_rgb_frame"/>

  <joint name="oakd_rgb_optical_joint" type="fixed">
    <parent link="oakd_rgb_frame"/>
    <child link="oakd_rgb_optical_frame"/>
    <origin xyz="0 0 0" rpy="-1.57 0 -1.57"/>
  </joint>
  <link name="oakd_rgb_optical_frame"/>

  <joint name="oakd_left_joint" type="fixed">
    <parent link="oakd_link"/>
    <child link="oakd_left_frame"/>
    <origin xyz="0 0.0375 0" rpy="0 0 0"/>
  </joint>
  <link name="oakd_left_frame"/>

  <joint name="oakd_left_optical_joint" type="fixed">
    <parent link="oakd_left_frame"/>
    <child link="oakd_left_optical_frame"/>
    <origin xyz="0 0 0" rpy="-1.57 0 -1.57"/>
  </joint>
  <link name="oakd_left_optical_frame"/>

  <joint name="oakd_right_joint" type="fixed">
    <parent link="oakd_link"/>
    <child link="oakd_right_frame"/>
    <origin xyz="0 -0.0375 0" rpy="0 0 0"/>
  </joint>
  <link name="oakd_right_frame"/>

  <joint name="oakd_right_optical_joint" type="fixed">
    <parent link="oakd_right_frame"/>
    <child link="oakd_right_optical_frame"/>
    <origin xyz="0 0 0" rpy="-1.57 0 -1.57"/>
  </joint>
  <link name="oakd_right_optical_frame"/>


  <gazebo reference="oakd_rgb_frame">
    <sensor name="rgb_camera" type="camera">
      <always_on>true</always_on>
      <update_rate>30</update_rate>
      <camera>
        <horizontal_fov>1.274</horizontal_fov>
        <image>
          <width>1280</width> <height>720</height> <format>R8G8B8</format>
        </image>
        <clip><near>0.2</near><far>20</far></clip>
      </camera>
      <plugin name="rgb_camera_controller" filename="libgazebo_ros_camera.so">
        <ros>
          <remapping>image_raw:=oakd/rgb/image_raw</remapping>
          <remapping>camera_info:=oakd/rgb/camera_info</remapping>
        </ros>
        <frame_name>oakd_rgb_optical_frame</frame_name>
      </plugin>
    </sensor>
  </gazebo>

  <gazebo reference="oakd_left_frame">
    <sensor name="left_camera" type="camera">
      <always_on>true</always_on>
      <update_rate>30</update_rate>
      <camera>
        <horizontal_fov>1.274</horizontal_fov>
        <image>
          <width>1280</width> <height>720</height> <format>L8</format>
        </image>
        <clip><near>0.2</near><far>20</far></clip>
      </camera>
      <plugin name="left_camera_controller" filename="libgazebo_ros_camera.so">
        <ros>
          <remapping>image_raw:=oakd/left/image_raw</remapping>
          <remapping>camera_info:=oakd/left/camera_info</remapping>
        </ros>
        <frame_name>oakd_left_optical_frame</frame_name>
      </plugin>
    </sensor>
  </gazebo>

  <gazebo reference="oakd_right_frame">
    <sensor name="right_camera" type="camera">
      <always_on>true</always_on>
      <update_rate>30</update_rate>
      <camera>
        <horizontal_fov>1.274</horizontal_fov>
        <image>
          <width>1280</width> <height>720</height> <format>L8</format>
        </image>
        <clip><near>0.2</near><far>20</far></clip>
      </camera>
      <plugin name="right_camera_controller" filename="libgazebo_ros_camera.so">
        <ros>
          <remapping>image_raw:=oakd/right/image_raw</remapping>
          <remapping>camera_info:=oakd/right/camera_info</remapping>
        </ros>
        <frame_name>oakd_right_optical_frame</frame_name>
      </plugin>
    </sensor>
  </gazebo>
</robot>
