<?xml version="1.0" ?>
<robot name="turtlebot3_burger_ultimate" xmlns:xacro="http://ros.org/wiki/xacro">

  <material name="black"><color rgba="0.0 0.0 0.0 1.0"/></material>
  <material name="dark"><color rgba="0.3 0.3 0.3 1.0"/></material>
  <material name="light_black"><color rgba="0.4 0.4 0.4 1.0"/></material>
  <material name="blue"><color rgba="0.0 0.0 0.8 1.0"/></material>
  <material name="green"><color rgba="0.0 0.8 0.0 1.0"/></material>
  <material name="grey"><color rgba="0.5 0.5 0.5 1.0"/></material>

  <link name="base_footprint"/>

  <joint name="base_joint" type="fixed">
    <parent link="base_footprint"/>
    <child link="base_link"/>
    <origin rpy="0 0 0" xyz="0.0 0.0 0.010"/>
  </joint>

  <link name="base_link">
    <visual>
      <origin rpy="0 0 0" xyz="-0.032 0 0.0"/>
      <geometry>
        <mesh filename="package://turtlebot3_description/meshes/bases/burger_base.stl" scale="0.001 0.001 0.001"/>
      </geometry>
      <material name="light_black"/>
    </visual>
    <collision>
      <origin rpy="0 0 0" xyz="-0.032 0 0.070"/>
      <geometry>
        <box size="0.140 0.140 0.143"/>
      </geometry>
    </collision>
    <inertial>
      <origin rpy="0 0 0" xyz="-0.033 0 0.07"/>
      <mass value="0.82573504"/>
      <inertia ixx="2.2124416e-03" ixy="0.0" ixz="0.0" iyy="2.1193702e-03" iyz="0.0" izz="2.0064271e-03"/>
    </inertial>
  </link>

  <joint name="wheel_left_joint" type="continuous">
    <parent link="base_link"/>
    <child link="wheel_left_link"/>
    <origin rpy="-1.57 0 0" xyz="0.0 0.08 0.023"/>
    <axis xyz="0 0 1"/>
  </joint>
  <link name="wheel_left_link">
    <visual>
      <origin rpy="1.57 0 0" xyz="0 0 0"/>
      <geometry>
        <mesh filename="package://turtlebot3_description/meshes/wheels/left_tire.stl" scale="0.001 0.001 0.001"/>
      </geometry>
      <material name="dark"/>
    </visual>
    <collision>
      <origin rpy="0 0 0" xyz="0 0 0"/>
      <geometry>
        <cylinder length="0.018" radius="0.033"/>
      </geometry>
    </collision>
    <inertial>
      <origin xyz="0 0 0"/>
      <mass value="0.02849894"/>
      <inertia ixx="1.1175580e-05" ixy="0.0" ixz="0.0" iyy="1.1192413e-05" iyz="0.0" izz="2.0712558e-05"/>
    </inertial>
  </link>

  <joint name="wheel_right_joint" type="continuous">
    <parent link="base_link"/>
    <child link="wheel_right_link"/>
    <origin rpy="-1.57 0 0" xyz="0.0 -0.080 0.023"/>
    <axis xyz="0 0 1"/>
  </joint>
  <link name="wheel_right_link">
    <visual>
      <origin rpy="1.57 0 0" xyz="0 0 0"/>
      <geometry>
        <mesh filename="package://turtlebot3_description/meshes/wheels/right_tire.stl" scale="0.001 0.001 0.001"/>
      </geometry>
      <material name="dark"/>
    </visual>
    <collision>
      <origin rpy="0 0 0" xyz="0 0 0"/>
      <geometry>
        <cylinder length="0.018" radius="0.033"/>
      </geometry>
    </collision>
    <inertial>
      <origin xyz="0 0 0"/>
      <mass value="0.02849894"/>
      <inertia ixx="1.1175580e-05" ixy="0.0" ixz="0.0" iyy="1.1192413e-05" iyz="0.0" izz="2.0712558e-05"/>
    </inertial>
  </link>

  <joint name="caster_back_joint" type="fixed">
    <parent link="base_link"/>
    <child link="caster_back_link"/>
    <origin rpy="-1.57 0 0" xyz="-0.081 0 -0.004"/>
  </joint>
  <link name="caster_back_link">
    <collision>
      <origin rpy="0 0 0" xyz="0 0.001 0"/>
      <geometry>
        <box size="0.030 0.009 0.020"/>
      </geometry>
    </collision>
    <inertial>
      <origin xyz="0 0 0"/>
      <mass value="0.005"/>
      <inertia ixx="1.0e-07" ixy="0.0" ixz="0.0" iyy="1.0e-07" iyz="0.0" izz="1.0e-07"/>
    </inertial>
  </link>

  <joint name="imu_joint" type="fixed">
    <parent link="base_link"/>
    <child link="imu_link"/>
    <origin rpy="0 0 0" xyz="-0.032 0 0.068"/>
  </joint>
  <link name="imu_link"/>

  <joint name="scan_joint" type="fixed">
    <parent link="base_link"/>
    <child link="base_scan"/>
    <origin rpy="0 0 0" xyz="-0.032 0 0.172"/>
  </joint>
  <link name="base_scan">
    <visual>
      <origin rpy="0 0 0" xyz="0 0 0.0"/>
      <geometry>
        <mesh filename="package://turtlebot3_description/meshes/sensors/lds.stl" scale="0.001 0.001 0.001"/>
      </geometry>
      <material name="dark"/>
    </visual>
    <collision>
      <origin rpy="0 0 0" xyz="0.015 0 -0.0065"/>
      <geometry>
        <cylinder length="0.0315" radius="0.055"/>
      </geometry>
    </collision>
    <inertial>
      <mass value="0.114"/>
      <origin xyz="0 0 -0.01"/>
      <inertia ixx="47.43e-06" ixy="0.0" ixz="0.0" iyy="79.51e-06" iyz="0.0" izz="102.75e-06"/>
    </inertial>
  </link>

  <joint name="gripper_base_joint" type="fixed">
    <parent link="base_link"/>
    <child link="base_gripper"/>
    <origin rpy="0 0 0" xyz="0.052 0.0025 0.04"/>
  </joint>

  <link name="base_gripper">
    <visual>
      <origin rpy="0 0 0" xyz="0 0 0.0"/>
      <geometry>
        <mesh filename="package://tb3_autonomy/meshes/gripper_base.stl" scale="0.001 0.001 0.001"/>
      </geometry>
      <material name="dark"/>
    </visual>
    <collision>
      <origin rpy="0 0 0" xyz="0 0 -0.01"/>
      <geometry>
        <box size="0.03 0.055 0.06"/>
      </geometry>
    </collision>
    <inertial>
       <origin xyz="0 0 0"/>
       <mass value="0.06"/>
       <inertia ixx="23.84e-06" ixy="0.0" ixz="0.0" iyy="16.238e-06" iyz="0.0" izz="13.47e-06"/>
    </inertial>
  </link>

  <link name="tilt_gripper">
    <visual>
      <origin rpy="0 0 0" xyz="0 0 0.0"/>
      <geometry>
        <mesh filename="package://tb3_autonomy/meshes/gripper_tilt.stl" scale="0.001 0.001 0.001"/>
      </geometry>
      <material name="dark"/>
    </visual>
    <collision>
      <origin rpy="0 0 0" xyz="0.045 0 0"/>
      <geometry>
        <box size="0.055 0.075 0.06"/>
      </geometry>
    </collision>
    <inertial>
        <origin xyz="0.025 0 0"/>
        <mass value="0.060"/>
        <inertia ixx="23.15e-06" ixy="0.0" ixz="0.0" iyy="32.9e-06" iyz="0.0" izz="42.567e-06"/>
    </inertial>
  </link>
  <joint name="gripper_tilt_joint" type="revolute">
      <axis xyz="0 1 0"/>
      <limit effort="1000.0" lower="-0.3" upper="0" velocity="0.5"/>
      <origin rpy="0 0 0" xyz="0 0.002 0"/>
      <parent link="base_gripper"/>
      <child link="tilt_gripper"/>
  </joint>

  <link name="left_gripper">
    <visual>
      <origin rpy="0 0 0" xyz="0 0 0.0"/>
      <geometry>
        <mesh filename="package://tb3_autonomy/meshes/gripper_left.stl" scale="0.001 0.001 0.001"/>
      </geometry>
      <material name="dark"/>
    </visual>
    <collision>
      <origin rpy="0 0 0" xyz="0.09 0 -0.02"/>
      <geometry>
        <box size="0.02 0.02 0.041"/>
      </geometry>
    </collision>
    <inertial>
        <origin xyz="0.045 0 -0.021"/>
        <mass value="0.120"/>
        <inertia ixx="23.07e-06" ixy="0.0" ixz="0.0" iyy="107.0e-06" iyz="0.0" izz="96.06e-06"/>
    </inertial>
  </link>
  <joint name="gripper_left_joint" type="revolute">
      <axis xyz="0 0 1"/>
      <limit effort="1000.0" lower="0" upper="1.0" velocity="0.5"/>
      <origin rpy="0 0 0" xyz="0.05 0.016 0.018"/>
      <parent link="tilt_gripper"/>
      <child link="left_gripper"/>
  </joint>

  <link name="right_gripper">
    <visual>
      <origin rpy="0 0 0" xyz="0 0 0.0"/>
      <geometry>
        <mesh filename="package://tb3_autonomy/meshes/gripper_right.stl" scale="0.001 0.001 0.001"/>
      </geometry>
      <material name="dark"/>
    </visual>
    <collision>
      <origin rpy="0 0 0" xyz="0.09 0 -0.02"/>
      <geometry>
        <box size="0.02 0.02 0.041"/>
      </geometry>
    </collision>
    <inertial>
        <origin xyz="0.045 0.0 -0.021"/>
        <mass value="0.120"/>
        <inertia ixx="23.20e-06" ixy="0.0" ixz="0.0" iyy="107.33e-06" iyz="0.0" izz="96.18e-06"/>
    </inertial>
  </link>
  <joint name="gripper_right_joint" type="revolute">
      <axis xyz="0 0 1"/>
      <limit effort="1000.0" lower="-1.0" upper="0" velocity="0.5"/>
      <origin rpy="0 0 0" xyz="0.05 -0.016 0.018"/>
      <parent link="tilt_gripper"/>
      <child link="right_gripper"/>
  </joint>

  <link name="oak_d_pro_camera">
    <visual name="meshes">
      <origin xyz="0.0 0.0 0.0" rpy="0 0 0"/>
      <geometry>
          <mesh filename="package://tb3_autonomy/meshes/OAK-D-PRO.stl" scale="1.0 1.0 1.0"/>
      </geometry>
      <material name="dark"/>
    </visual>
    <collision>
      <origin rpy="0.0 0.0 0.0" xyz="0 -0.005 -0.01"/>
      <geometry>
        <box size="0.1 0.03 0.02"/>
      </geometry>
    </collision>
    <inertial>
      <origin xyz="0.00099391 -0.00585275 -0.01028175"/>
      <mass value="0.091"/>
      <inertia ixx="0.00000975" ixy="0.0" ixz="0.0" iyy="0.00007087" iyz="0.0" izz="0.00007312"/>
    </inertial>  
  </link>

  <joint name="joint_oak_d_pro_camera" type="fixed">
    <parent link="base_link"/>
    <child link="oak_d_pro_camera"/>
    <origin xyz="0.09 0.0 0.145" rpy="1.57 0.0 1.57"/> 
  </joint>
  
  <link name="oak_d_pro_color_optical_frame"/>   
  <joint name="joint_oak_d_pro_color_optical_frame" type="fixed">
    <parent link="oak_d_pro_camera"/>
    <child link="oak_d_pro_color_optical_frame"/>
    <origin xyz="0.0 0.0 0.0" rpy="-1.5708 0.0 -1.5708"/> 
  </joint>
  
  <link name="oak_d_pro_depth_optical_frame"/>   
  <joint name="oak_d_pro_depth_optical_frame" type="fixed">
    <parent link="oak_d_pro_camera"/>
    <child link="oak_d_pro_depth_optical_frame"/>
    <origin xyz="0.0 0.0 0.0" rpy="-1.5708 0.0 -1.5708"/> 
  </joint>
<link name="counterweight_link">
    <visual>
      <origin xyz="0 0 0" rpy="0 0 0"/>
      <geometry>
        <box size="0.05 0.1 0.05"/> </geometry>
      <material name="blue"/>
    </visual>
    <inertial>
      <origin xyz="0 0 0" rpy="0 0 0"/>
      <mass value="0.5"/> <inertia ixx="0.01" ixy="0" ixz="0" iyy="0.01" iyz="0" izz="0.01"/>
    </inertial>
  </link>

  <joint name="counterweight_joint" type="fixed">
    <parent link="base_link"/>
    <child link="counterweight_link"/>
    <origin xyz="-0.15 0 0.05" rpy="0 0 0"/>
  </joint>
  
  <gazebo>
    <plugin name="turtlebot3_diff_drive" filename="libgazebo_ros_diff_drive.so">
      <ros></ros>
      <update_rate>30</update_rate>
      <left_joint>wheel_left_joint</left_joint>
      <right_joint>wheel_right_joint</right_joint>
      <wheel_separation>0.160</wheel_separation>
      <wheel_diameter>0.066</wheel_diameter>
      <max_wheel_torque>20</max_wheel_torque>
      <max_wheel_acceleration>1.0</max_wheel_acceleration>
      <command_topic>cmd_vel</command_topic>
      <publish_odom>true</publish_odom>
      <publish_odom_tf>true</publish_odom_tf>
      <publish_wheel_tf>false</publish_wheel_tf>
      <odometry_topic>odom</odometry_topic>
      <odometry_frame>odom</odometry_frame>
      <robot_base_frame>base_footprint</robot_base_frame>
    </plugin>

    <plugin name="turtlebot3_joint_state" filename="libgazebo_ros_joint_state_publisher.so">
      <ros>
        <remapping>~/out:=joint_states</remapping>
      </ros>
      <update_rate>30</update_rate>
      <joint_name>wheel_left_joint</joint_name>
      <joint_name>wheel_right_joint</joint_name>
    </plugin>
  </gazebo>

  <gazebo reference="wheel_left_link">
    <mu1>0.1</mu1><mu2>0.1</mu2>
    <kp>500000.0</kp><kd>10.0</kd>
    <minDepth>0.001</minDepth>
    <maxVel>0.1</maxVel>
    <fdir1>1 0 0</fdir1>
    <material>Gazebo/FlatBlack</material>
  </gazebo>
  <gazebo reference="wheel_right_link">
    <mu1>0.1</mu1><mu2>0.1</mu2>
    <kp>500000.0</kp><kd>10.0</kd>
    <minDepth>0.001</minDepth>
    <maxVel>0.1</maxVel>
    <fdir1>1 0 0</fdir1>
    <material>Gazebo/FlatBlack</material>
  </gazebo>

  <gazebo reference="base_scan">
    <sensor name="hls_lfcd_lds" type="ray">
      <always_on>true</always_on>
      <visualize>false</visualize> <pose>0 0 0 0 0 0</pose>
      <update_rate>5</update_rate>
      <ray>
        <scan>
          <horizontal>
            <samples>360</samples>
            <resolution>1</resolution>
            <min_angle>0.0</min_angle>
            <max_angle>6.28319</max_angle>
          </horizontal>
        </scan>
        <range>
          <min>0.120</min>
          <max>3.5</max>
          <resolution>0.015</resolution>
        </range>
        <noise>
          <type>gaussian</type>
          <mean>0.0</mean>
          <stddev>0.01</stddev>
        </noise>
      </ray>
      <plugin name="turtlebot3_laserscan" filename="libgazebo_ros_ray_sensor.so">
        <ros>
          <remapping>~/out:=scan</remapping>
        </ros>
        <output_type>sensor_msgs/LaserScan</output_type>
        <frame_name>base_scan</frame_name>
      </plugin>
    </sensor>
  </gazebo>

  <gazebo reference="oak_d_pro_color_optical_frame">
    <sensor name="rgb_camera" type="camera">
      <pose>0 0 0 -1.57 0 -1.57</pose>
      
      <always_on>true</always_on>
      <update_rate>30</update_rate>
      <visualize>true</visualize>
      <topic>oakd/rgb/image_raw</topic>
      <camera>
        <horizontal_fov>1.047</horizontal_fov>
        <image>
          <width>640</width> <height>480</height> <format>R8G8B8</format>
        </image>
        <clip>
          <near>0.1</near> <far>100</far>
        </clip>
      </camera>
      <plugin name="camera_controller" filename="libgazebo_ros_camera.so">
        <ros>
          <remapping>image_raw:=oakd/rgb/image_raw</remapping>
          <remapping>camera_info:=oakd/rgb/camera_info</remapping>
        </ros>
        <frame_name>oak_d_pro_color_optical_frame</frame_name>
      </plugin>
    </sensor>
  </gazebo>

  <gazebo reference="oak_d_pro_depth_optical_frame">
    <sensor name="depth_camera" type="depth">
      <pose>0 0 0 -1.57 0 -1.57</pose>

      <always_on>true</always_on>
      <update_rate>30</update_rate>
      <visualize>true</visualize>
      <topic>oakd/depth/image_raw</topic>
      <camera>
        <horizontal_fov>1.047</horizontal_fov>
        <image>
          <width>640</width> <height>480</height> <format>R_FLOAT32</format>
        </image>
        <clip>
          <near>0.2</near> <far>10.0</far>
        </clip>
      </camera>
      <plugin name="depth_camera_controller" filename="libgazebo_ros_camera.so">
        <ros>
          <remapping>image_raw:=oakd/depth/image_raw</remapping>
          <remapping>camera_info:=oakd/depth/camera_info</remapping>
          <remapping>depth/image_raw:=oakd/depth/image_raw</remapping>
        </ros>
        <frame_name>oak_d_pro_depth_optical_frame</frame_name>
        <min_depth>0.2</min_depth>
        <max_depth>10.0</max_depth>
      </plugin>
    </sensor>
  </gazebo>

  <gazebo reference="imu_link">
    <sensor name="tb3_imu" type="imu">
      <always_on>true</always_on>
      <update_rate>200</update_rate>
      <imu>
        <angular_velocity>
          <x><noise type="gaussian"><mean>0.0</mean><stddev>2e-4</stddev></noise></x>
          <y><noise type="gaussian"><mean>0.0</mean><stddev>2e-4</stddev></noise></y>
          <z><noise type="gaussian"><mean>0.0</mean><stddev>2e-4</stddev></noise></z>
        </angular_velocity>
        <linear_acceleration>
          <x><noise type="gaussian"><mean>0.0</mean><stddev>1.7e-2</stddev></noise></x>
          <y><noise type="gaussian"><mean>0.0</mean><stddev>1.7e-2</stddev></noise></y>
          <z><noise type="gaussian"><mean>0.0</mean><stddev>1.7e-2</stddev></noise></z>
        </linear_acceleration>
      </imu>
      <plugin name="turtlebot3_imu" filename="libgazebo_ros_imu_sensor.so">
        <ros>
          <remapping>~/out:=imu</remapping>
        </ros>
      </plugin>
    </sensor>
  </gazebo>
<gazebo reference="caster_back_link">
    <mu1>0.0</mu1>
    <mu2>0.0</mu2>
    <kp>1000000.0</kp>
    <kd>100.0</kd>
    <minDepth>0.001</minDepth>
    <maxVel>1.0</maxVel>
    <material>Gazebo/FlatBlack</material>
  </gazebo>
</robot>
